<?xml version="1.0"?>
<!-- http://wiki.ros.org/urdf/XML/link -->
<robot name="reto_robot">
    <link name="base_link">
    <visual>
        <geometry>
            <cylinder length="0.05" radius="0.2"/>
        </geometry>
        <!--orig he reference frame of the visual element with respect to the
        reference frame of the link -->
        <!-- rpy - r is roll, p-pitch and y -yaw -->
        <!-- xyz - x,y,z -offsets -->
        <origin rpy="0 0 0" xyz="0 0 0"/>
        <material name="yellow">
            <color rgba="1 1 0 1"/> |
        </material>
    </visual>
    </link>

    <joint name="joint_1" type="revolute">
        <parent link="base_link"/>
        <child link="first_link"/>
            <origin xyz="0 0 0.025"/>
            <axis xyz="0 0 1"/>
            <limit effort="300" velocity="2.0" lower="-3.14" upper="3.14" />
    </joint>

    <link name="first_link">
    <visual>
        <geometry>
            <cylinder length="0.5" radius="0.04"/>
        </geometry>
        <origin rpy="0 0 0" xyz="0 0 0.25 " />
        <material name="red">
            <color rgba="0 0 1 1"/>
        </material>
    </visual>
    </link>

    <joint name="joint_2" type="revolute">
        <parent link="first_link"/>
        <child link="second_link"/>
            <origin xyz="0 0 0.5"/>
            <axis xyz="0 1 0"/>
            <limit effort="300" velocity="2.0" lower="-1.2" upper="1.2" />
    </joint>

    <link name="second_link">
    <visual>
        <geometry>
            <cylinder length="0.5" radius="0.04"/>
        </geometry>
        <origin rpy="0 1.57 0" xyz="0 0 0" />
        <material name="blue">
            <color rgba="0 1 0 1"/>
        </material>
    </visual>
    </link>

</robot>